Workbook
Name SUM: #REF!

Sheet RS ANDHIKA
A1: BREAKDOWN PENJUALAN PT. MITRAJAYA SELARAS ABADI
A7: 2025 RSU ANDHIKA
A12: JANUARI 2025
A13: No. | B13: Faktur | D13: Nama Pelanggan | E13: Produk | F13: Quantity | H13: Harga Satuan | I13: Jumlah Harga | J13: Dics. | K13: Jumlah | L13: Jumlah | M13: Total | N13: PPN 11% | O13: PPH 1,5 % | P13: Total Tghan | Q13: DISTRIBUTOR | R13: Harga Pokok | S13: Harga Pokok | T13: DISCOUNT DISTRIBUTOR | U13: JUMLAH | V13: TOTAL | W13: TOTAL PMBELIAN | X13: PPN | Y13: TOTAL
B14: Tanggal | C14: No. Faktur | F14: jml | G14: Satuan | H14: ( Rp ) | I14: ( Rp ) | J14: ( % ) | K14: Discon ( Rp ) | L14: setelah Disc | M14: Tagihan | P14: stlh PPN | R14: beli (Satuan) | S14: beli (Total) | T14: % | U14: DISC | V14: STLH DISC | W14: SBLM PPN
A15: 1 | B15: 45660 | C15: 117180125 | D15: RS Andhika | E15: Albumin 160ml Mindray | F15: 1 | G15: kit | H15: 627000 | I15: =SUM(F15*H15) -> 627000 | J15: 0 | K15: =SUM(I15*J15) -> 0 | L15: =SUM(I15-K15) -> 627000 | M15: =SUM(L15:L62) -> 1.117776e+08 | N15: =SUM(M15*11%) -> 12295536 | P15: =SUM(M15+N15) -> 1.2407313e+08 | Q15: PT TRIPATRIA ANDALAN MERDEKA | R15: 270930 | S15: =SUM(F15*R15) -> 270930 | T15: 0 | U15: =SUM(S15*T15) -> 0 | V15: =SUM(S15-U15) -> 270930 | W15: =SUM(V15) -> 270930 | X15: 0.11 | Y15: =SUM(W15+(W15*X15)) -> 300732.3
E16: Alkohol Swab Sensi | F16: 25 | G16: box | H16: 27000 | I16: =SUM(F16*H16) -> 675000 | J16: 0.2 | K16: =SUM(I16*J16) -> 135000 | L16: =SUM(I16-K16) -> 540000 | Q16: SMS PRAMUKA | R16: 15000 | S16: =SUM(F16*R16) -> 375000 | T16: 0 | U16: =SUM(S16*T16) -> 0 | V16: =SUM(S16-U16) -> 375000 | W16: =SUM(V16) -> 375000 | X16: 0 | Y16: =SUM(W16+(W16*X16)) -> 375000
E17: ALT 176 ml Mindray | F17: 1 | G17: kit | H17: 983000 | I17: =SUM(F17*H17) -> 983000 | J17: 0 | K17: =SUM(I17*J17) -> 0 | L17: =SUM(I17-K17) -> 983000 | Q17: PT TRIPATRIA ANDALAN MERDEKA | R17: 424765 | S17: =SUM(F17*R17) -> 424765 | T17: 0 | U17: =SUM(S17*T17) -> 0 | V17: =SUM(S17-U17) -> 424765 | W17: =SUM(V17) -> 424765 | X17: 0.11 | Y17: =SUM(W17+(W17*X17)) -> 471489.15
E18: CK-MB Neo Ichroma | F18: 1 | G18: box | H18: 4583750 | I18: =SUM(F18*H18) -> 4583750 | J18: 0.2 | K18: =SUM(I18*J18) -> 916750 | L18: =SUM(I18-K18) -> 3667000 | Q18: PT ZOE PELITA NUSANTARA | R18: 1625000 | S18: =SUM(F18*R18) -> 1625000 | T18: 0.25 | U18: =SUM(S18*T18) -> 406250 | V18: =SUM(S18-U18) -> 1218750 | W18: =SUM(V18) -> 1218750 | X18: 0.11 | Y18: =SUM(W18+(W18*X18)) -> 1352812.5
E19: CRP isi 25 test/box ichroma | F19: 2 | G19: box | H19: 2603750 | I19: =SUM(F19*H19) -> 5207500 | J19: 0.2 | K19: =SUM(I19*J19) -> 1041500 | L19: =SUM(I19-K19) -> 4166000 | Q19: PT ZOE PELITA NUSANTARA | R19: 1562500 | S19: =SUM(F19*R19) -> 3125000 | T19: 0.25 | U19: =SUM(S19*T19) -> 781250 | V19: =SUM(S19-U19) -> 2343750 | W19: =SUM(V19) -> 2343750 | X19: 0.11 | Y19: =SUM(W19+(W19*X19)) -> 2601562.5
E20: Determine HBSAG 100T | F20: 3 | G20: box | H20: 3019000 | I20: =SUM(F20*H20) -> 9057000 | J20: 0.2 | K20: =SUM(I20*J20) -> 1811400 | L20: =SUM(I20-K20) -> 7245600 | Q20: PT SINERGI UTAMA SEJAHTERA | R20: 2173500 | S20: =SUM(F20*R20) -> 6520500 | T20: 0.2 | U20: =SUM(S20*T20) -> 1304100 | V20: =SUM(S20-U20) -> 5216400 | W20: =SUM(V20) -> 5216400 | X20: 0.11 | Y20: =SUM(W20+(W20*X20)) -> 5790204
E21: Glove nitril non sterile size S sritrang | F21: 25 | G21: box | H21: 87500 | I21: =SUM(F21*H21) -> 2187500 | J21: 0.2 | K21: =SUM(I21*J21) -> 437500 | L21: =SUM(I21-K21) -> 1750000 | Q21: HANALAB | R21: 36036 | S21: =SUM(F21*R21) -> 900900 | T21: 0 | U21: =SUM(S21*T21) -> 0 | V21: =SUM(S21-U21) -> 900900 | W21: =SUM(V21) -> 900900 | X21: 0.11 | Y21: =SUM(W21+(W21*X21)) -> 999999
E22: GOLDAR Anti A (1 vial) BIOCON | F22: 1 | G22: vial | H22: 187500 | I22: =SUM(F22*H22) -> 187500 | J22: 0.2 | K22: =SUM(I22*J22) -> 37500 | L22: =SUM(I22-K22) -> 150000 | Q22: PT BAVARIA | R22: 102000 | S22: =SUM(F22*R22) -> 102000 | T22: 0.2 | U22: =SUM(S22*T22) -> 20400 | V22: =SUM(S22-U22) -> 81600 | W22: =SUM(V22) -> 81600 | X22: 0.11 | Y22: =SUM(W22+(W22*X22)) -> 90576
E23: GOLDAR Anti B (1 vial) BIOCON | F23: 1 | G23: vial | H23: 187500 | I23: =SUM(F23*H23) -> 187500 | J23: 0.2 | K23: =SUM(I23*J23) -> 37500 | L23: =SUM(I23-K23) -> 150000 | Q23: PT BAVARIA | R23: 85000 | S23: =SUM(F23*R23) -> 85000 | T23: 0.2 | U23: =SUM(S23*T23) -> 17000 | V23: =SUM(S23-U23) -> 68000 | W23: =SUM(V23) -> 68000 | X23: 0.11 | Y23: =SUM(W23+(W23*X23)) -> 75480
E24: GOLDAR Anti D (1 vial) BIOCON | F24: 1 | G24: vial | H24: 225000 | I24: =SUM(F24*H24) -> 225000 | J24: 0.2 | K24: =SUM(I24*J24) -> 45000 | L24: =SUM(I24-K24) -> 180000 | Q24: PT BAVARIA | R24: 162000 | S24: =SUM(F24*R24) -> 162000 | T24: 0.2 | U24: =SUM(S24*T24) -> 32400 | V24: =SUM(S24-U24) -> 129600 | W24: =SUM(V24) -> 129600 | X24: 0.11 | Y24: =SUM(W24+(W24*X24)) -> 143856
E25: GOLDAR Anti D (1 vial) BAV | F25: 1 | G25: vial | H25: 225000 | I25: =SUM(F25*H25) -> 225000 | J25: 0.2 | K25: =SUM(I25*J25) -> 45000 | L25: =SUM(I25-K25) -> 180000 | Q25: PT BAVARIA | R25: 162000 | S25: =SUM(F25*R25) -> 162000 | T25: 0.2 | U25: =SUM(S25*T25) -> 32400 | V25: =SUM(S25-U25) -> 129600 | W25: =SUM(V25) -> 129600 | X25: 0.11 | Y25: =SUM(W25+(W25*X25)) -> 143856
E26: HbA1c isi 25 test/box Ichroma | F26: 5 | G26: box | H26: 2708750 | I26: =SUM(F26*H26) -> 13543750 | J26: 0.2 | K26: =SUM(I26*J26) -> 2708750 | L26: =SUM(I26-K26) -> 10835000 | Q26: PT ZOE PELITA NUSANTARA | R26: 1625000 | S26: =SUM(F26*R26) -> 8125000 | T26: 0.25 | U26: =SUM(S26*T26) -> 2031250 | V26: =SUM(S26-U26) -> 6093750 | W26: =SUM(V26) -> 6093750 | X26: 0.11 | Y26: =SUM(W26+(W26*X26)) -> 6764062.5
E27: HCG Device 25 test/box Orient Gene | F27: 4 | G27: box | H27: 235000 | I27: =SUM(F27*H27) -> 940000 | J27: 0.2 | K27: =SUM(I27*J27) -> 188000 | L27: =SUM(I27-K27) -> 752000 | Q27: PT LINTANG DIAGNOSTIK | R27: 190000 | S27: =SUM(F27*R27) -> 760000 | T27: 0.5 | U27: =SUM(S27*T27) -> 380000 | V27: =SUM(S27-U27) -> 380000 | W27: =SUM(V27) -> 380000 | X27: 0.11 | Y27: =SUM(W27+(W27*X27)) -> 421800
... E62: ichroma Trop I Plus | F62: 1 | G62: box | H62: 5000000 | I62: =SUM(F62*H62) -> 5000000 | J62: 0.2 | K62: =SUM(I62*J62) -> 1000000 | L62: =SUM(I62-K62) -> 4000000 | Q62: PT ZOE PELITA NUSANTARA | R62: 3000000 | S62: =SUM(F62*R62) -> 3000000 | T62: 0.25 | U62: =SUM(S62*T62) -> 750000 | V62: =SUM(S62-U62) -> 2250000 | W62: =SUM(V62) -> 2250000 | X62: 0.11 | Y62: =SUM(W62+(W62*X62)) -> 2497500
A63: 2 | B63: 45660 | C63: 117190125 | D63: RS Andhika | E63: Calibrant Fluid Pack CP100 EDAN | F63: 3 | G63: pack | H63: 3200000 | I63: =SUM(F63*H63) -> 9600000 | J63: 0 | K63: =SUM(I63*J63) -> 0 | L63: =SUM(I63-K63) -> 9600000 | M63: =SUM(L63:L65) -> 49400000 | N63: =SUM(M63*11%) -> 5434000 | P63: =SUM(M63+N63) -> 54834000 | Q63: PT NUSANTARA MEDCARE INDONESIA | R63: 1100000 | S63: =SUM(F63*R63) -> 3300000 | T63: 0 | U63: =SUM(S63*T63) -> 0 | V63: =SUM(S63-U63) -> 3300000 | W63: =SUM(V63) -> 3300000 | X63: 0.11 | Y63: =SUM(W63+(W63*X63)) -> 3663000
E64: Test Cartridge BG3 EDAN | F64: 1 | G64: set | H64: 13700000 | I64: =SUM(F64*H64) -> 13700000 | J64: 0 | K64: =SUM(I64*J64) -> 0 | L64: =SUM(I64-K64) -> 13700000 | Q64: PT NUSANTARA MEDCARE INDONESIA | R64: 4800000 | S64: =SUM(F64*R64) -> 4800000 | T64: 0 | U64: =SUM(S64*T64) -> 0 | V64: =SUM(S64-U64) -> 4800000 | W64: =SUM(V64) -> 4800000 | X64: 0.11 | Y64: =SUM(W64+(W64*X64)) -> 5328000
E65: Test Cartridge SC4 EDAN | F65: 3 | G65: set | H65: 8700000 | I65: =SUM(F65*H65) -> 26100000 | J65: 0 | K65: =SUM(I65*J65) -> 0 | L65: =SUM(I65-K65) -> 26100000 | Q65: PT NUSANTARA MEDCARE INDONESIA | R65: 3500000 | S65: =SUM(F65*R65) -> 10500000 | T65: 0 | U65: =SUM(S65*T65) -> 0 | V65: =SUM(S65-U65) -> 10500000 | W65: =SUM(V65) -> 10500000 | X65: 0.11 | Y65: =SUM(W65+(W65*X65)) -> 11655000
A66: 3 | B66: 45670 | C66: 117240125 | D66: RS Andhika | E66: Disposable Syiringe 10 cc Onemed | F66: 10 | G66: box | H66: 250000 | I66: =SUM(F66*H66) -> 2500000 | J66: 0.2 | K66: =SUM(I66*J66) -> 500000 | L66: =SUM(I66-K66) -> 2000000 | M66: =SUM(L66:L72) -> 7775800 | N66: =SUM(M66*11%) -> 855338 | P66: =SUM(M66+N66) -> 8631138 | Q66: PT INTI MEDICOM RETAILINDO | R66: 90090 | S66: =SUM(F66*R66) -> 900900 | T66: 0 | U66: =SUM(S66*T66) -> 0 | V66: =SUM(S66-U66) -> 900900 | W66: =SUM(V66) -> 900900 | X66: 0.11 | Y66: =SUM(W66+(W66*X66)) -> 999999
E67: Disposable Syiringe 1 cc Onemed | F67: 10 | G67: box | H67: 160000 | I67: =SUM(F67*H67) -> 1600000 | J67: 0.2 | K67: =SUM(I67*J67) -> 320000 | L67: =SUM(I67-K67) -> 1280000 | Q67: PT INTI MEDICOM RETAILINDO | R67: 57658 | S67: =SUM(F67*R67) -> 576580 | T67: 0 | U67: =SUM(S67*T67) -> 0 | V67: =SUM(S67-U67) -> 576580 | W67: =SUM(V67) -> 576580 | X67: 0.11 | Y67: =SUM(W67+(W67*X67)) -> 640003.8
E68: Disposable Syiringe 20 cc Onemed | F68: 4 | G68: box | H68: 172500 | I68: =SUM(F68*H68) -> 690000 | J68: 0.2 | K68: =SUM(I68*J68) -> 138000 | L68: =SUM(I68-K68) -> 552000 | Q68: PT INTI MEDICOM RETAILINDO | R68: 62162 | S68: =SUM(F68*R68) -> 248648 | T68: 0 | U68: =SUM(S68*T68) -> 0 | V68: =SUM(S68-U68) -> 248648 | W68: =SUM(V68) -> 248648 | X68: 0.11 | Y68: =SUM(W68+(W68*X68)) -> 275999.28
E69: Disposable Syiringe 3 cc Onemed | F69: 15 | G69: box | H69: 145000 | I69: =SUM(F69*H69) -> 2175000 | J69: 0.2 | K69: =SUM(I69*J69) -> 435000 | L69: =SUM(I69-K69) -> 1740000 | Q69: PT INTI MEDICOM RETAILINDO | R69: 52252 | S69: =SUM(F69*R69) -> 783780 | T69: 0 | U69: =SUM(S69*T69) -> 0 | V69: =SUM(S69-U69) -> 783780 | W69: =SUM(V69) -> 783780 | X69: 0.11 | Y69: =SUM(W69+(W69*X69)) -> 869995.8
E70: Disposable Syiringe 50 cc Onemed | F70: 4 | G70: box | H70: 200000 | I70: =SUM(F70*H70) -> 800000 | J70: 0.2 | K70: =SUM(I70*J70) -> 160000 | L70: =SUM(I70-K70) -> 640000 | Q70: PT INTI MEDICOM RETAILINDO | R70: 72072 | S70: =SUM(F70*R70) -> 288288 | T70: 0 | U70: =SUM(S70*T70) -> 0 | V70: =SUM(S70-U70) -> 288288 | W70: =SUM(V70) -> 288288 | X70: 0.11 | Y70: =SUM(W70+(W70*X70)) -> 319999.68
E71: Disposable Syiringe 5 cc Onemed | F71: 10 | G71: box | H71: 157500 | I71: =SUM(F71*H71) -> 1575000 | J71: 0.2 | K71: =SUM(I71*J71) -> 315000 | L71: =SUM(I71-K71) -> 1260000 | Q71: PT INTI MEDICOM RETAILINDO | R71: 56757 | S71: =SUM(F71*R71) -> 567570 | T71: 0 | U71: =SUM(S71*T71) -> 0 | V71: =SUM(S71-U71) -> 567570 | W71: =SUM(V71) -> 567570 | X71: 0.11 | Y71: =SUM(W71+(W71*X71)) -> 630002.7
E72: Theeway Stop Cock tanpa selang Onemed | F72: 2 | G72: box | H72: 189875 | I72: =SUM(F72*H72) -> 379750 | J72: 0.2 | K72: =SUM(I72*J72) -> 75950 | L72: =SUM(I72-K72) -> 303800 | Q72: PT INTI MEDICOM RETAILINDO | R72: 106306 | S72: =SUM(F72*R72) -> 212612 | T72: 0 | U72: =SUM(S72*T72) -> 0 | V72: =SUM(S72-U72) -> 212612 | W72: =SUM(V72) -> 212612 | X72: 0.11 | Y72: =SUM(W72+(W72*X72)) -> 235999.32
A73: 9 | B73: 45667 | C73: 117250125 | D73: RS Andhika | E73: Disposable Syiringe 20 cc Terumo | F73: 2 | G73: kit | H73: 390000 | I73: =SUM(F73*H73) -> 780000 | J73: 0.2 | K73: =SUM(I73*J73) -> 156000 | L73: =SUM(I73-K73) -> 624000 | M73: =SUM(L73:L75) -> 7300000 | N73: =SUM(M73*11%) -> 803000 | P73: =SUM(M73+N73) -> 8103000 | Q73: HANALAB | R73: 202703 | S73: =SUM(F73*R73) -> 405406 | T73: 0 | U73: =SUM(S73*T73) -> 0 | V73: =SUM(S73-U73) -> 405406 | W73: =SUM(V73) -> 405406 | X73: 0.11 | Y73: =SUM(W73+(W73*X73)) -> 450000.66
E74: Disposable Syiringe 20 cc Onemed | F74: 2 | G74: kit | H74: 172500 | I74: =SUM(F74*H74) -> 345000 | J74: 0.2 | K74: =SUM(I74*J74) -> 69000 | L74: =SUM(I74-K74) -> 276000 | Q74: PT INTI MEDICOM RETAILINDO | R74: 62162 | S74: =SUM(F74*R74) -> 124324 | T74: 0 | U74: =SUM(S74*T74) -> 0 | V74: =SUM(S74-U74) -> 124324 | W74: =SUM(V74) -> 124324 | X74: 0.11 | Y74: =SUM(W74+(W74*X74)) -> 137999.64
E75: Glove latex non steril size s Free powder Sritrang | F75: 100 | G75: box | H75: 80000 | I75: =SUM(F75*H75) -> 8000000 | J75: 0.2 | K75: =SUM(I75*J75) -> 1600000 | L75: =SUM(I75-K75) -> 6400000 | Q75: HANALAB | R75: 32432 | S75: =SUM(F75*R75) -> 3243200 | T75: 0 | U75: =SUM(S75*T75) -> 0 | V75: =SUM(S75-U75) -> 3243200 | W75: =SUM(V75) -> 3243200 | X75: 0.11 | Y75: =SUM(W75+(W75*X75)) -> 3599952
A76: 5 | B76: 45670 | C76: =117310125 -> 117310125 | D76: RS Andhika | E76: Contour Plus BG Test Strip 1x50 | F76: 40 | G76: box | H76: 235360 | I76: =SUM(F76*H76) -> 9414400 | J76: 0.2 | K76: =SUM(I76*J76) -> 1882880 | L76: =SUM(I76-K76) -> 7531520 | M76: =SUM(L76:L84) -> 23858024 | N76: =SUM(M76*11%) -> 2624382.6 | P76: =SUM(M76+N76) -> 26482407 | Q76: PT GOBEL DHARMA NUSANTARA | R76: 154000 | S76: =SUM(F76*R76) -> 6160000 | T76: 0.25 | U76: =SUM(S76*T76) -> 1540000 | V76: =SUM(S76-U76) -> 4620000 | W76: =SUM(V76) -> 4620000 | X76: 0.11 | Y76: =SUM(W76+(W76*X76)) -> 5128200
E77: Insuline Pen Needle 32G x 4mm BD | F77: 2 | G77: box | H77: 316250 | I77: =SUM(F77*H77) -> 632500 | J77: 0.2 | K77: =SUM(I77*J77) -> 126500 | L77: =SUM(I77-K77) -> 506000 | Q77: HANALAB | R77: 189200 | S77: =SUM(F77*R77) -> 378400 | T77: 0 | U77: =SUM(S77*T77) -> 0 | V77: =SUM(S77-U77) -> 378400 | W77: =SUM(V77) -> 378400 | X77: 0.11 | Y77: =SUM(W77+(W77*X77)) -> 420024
E78: OK Plast isi 100 pcs/box | F78: 25 | G78: box | H78: 37500 | I78: =SUM(F78*H78) -> 937500 | J78: 0.2 | K78: =SUM(I78*J78) -> 187500 | L78: =SUM(I78-K78) -> 750000 | Q78: Agel Mandiri | R78: 20000 | S78: =SUM(F78*R78) -> 500000 | T78: 0 | U78: =SUM(S78*T78) -> 0 | V78: =SUM(S78-U78) -> 500000 | W78: =SUM(V78) -> 500000 | X78: 0 | Y78: =SUM(W78+(W78*X78)) -> 500000
E79: Thermal Papper Besar | F79: 10 | G79: roll | H79: 44938 | I79: =SUM(F79*H79) -> 449380 | J79: 0.2 | K79: =SUM(I79*J79) -> 89876 | L79: =SUM(I79-K79) -> 359504 | Q79: INTERMEDIA | R79: 6000 | S79: =SUM(F79*R79) -> 60000 | T79: 0 | U79: =SUM(S79*T79) -> 0 | V79: =SUM(S79-U79) -> 60000 | W79: =SUM(V79) -> 60000 | X79: 0 | Y79: =SUM(W79+(W79*X79)) -> 60000
E80: Crea 72 ml Mindray | F80: 2 | G80: kit | H80: 3328000 | I80: =SUM(F80*H80) -> 6656000 | J80: 0 | K80: =SUM(I80*J80) -> 0 | L80: =SUM(I80-K80) -> 6656000 | Q80: PT TRIPATRIA ANDALAN MERDEKA | R80: 500500 | S80: =SUM(F80*R80) -> 1001000 | T80: 0 | U80: =SUM(S80*T80) -> 0 | V80: =SUM(S80-U80) -> 1001000 | W80: =SUM(V80) -> 1001000 | X80: 0.11 | Y80: =SUM(W80+(W80*X80)) -> 1111110
E81: Spinocan No 26G BBraun | F81: 3 | G81: box | H81: 2000000 | I81: =SUM(F81*H81) -> 6000000 | J81: 0.2 | K81: =SUM(I81*J81) -> 1200000 | L81: =SUM(I81-K81) -> 4800000 | Q81: PT MARGO JAYA LESTARI | R81: 1200000 | S81: =SUM(F81*R81) -> 3600000 | T81: 0.1 | U81: =SUM(S81*T81) -> 360000 | V81: =SUM(S81-U81) -> 3240000 | W81: =SUM(V81) -> 3240000 | X81: 0.11 | Y81: =SUM(W81+(W81*X81)) -> 3596400
E82: Thermal Papper 4,9mm Mindray | F82: 10 | G82: roll | H82: 113500 | I82: =SUM(F82*H82) -> 1135000 | J82: 0 | K82: =SUM(I82*J82) -> 0 | L82: =SUM(I82-K82) -> 1135000 | Q82: PT SMS | R82: 13000 | S82: =SUM(F82*R82) -> 130000 | T82: 0 | U82: =SUM(S82*T82) -> 0 | V82: =SUM(S82-U82) -> 130000 | W82: =SUM(V82) -> 130000 | X82: 0.11 | Y82: =SUM(W82+(W82*X82)) -> 144300
E83: IV Cathetr with wing 18G Onemed | F83: 4 | G83: box | H83: 331250 | I83: =SUM(F83*H83) -> 1325000 | J83: 0.2 | K83: =SUM(I83*J83) -> 265000 | L83: =SUM(I83-K83) -> 1060000 | Q83: PT INTI MEDICOM RETAILINDO | R83: 130631 | S83: =SUM(F83*R83) -> 522524 | T83: 0 | U83: =SUM(S83*T83) -> 0 | V83: =SUM(S83-U83) -> 522524 | W83: =SUM(V83) -> 522524 | X83: 0.11 | Y83: =SUM(W83+(W83*X83)) -> 580001.64
...

Sheet PT MAIMUN TUAH
A1: BREAKDOWN PENJUALAN PT. MITRAJAYA SELARAS ABADI
A5: 2025
A10: JANUARI 2025
A11: No. | B11: Faktur | D11: Nama Pelanggan | E11: Produk | F11: Quantity | H11: Harga Satuan | I11: Jumlah Harga | J11: Dics. | K11: Jumlah | L11: Jumlah | M11: Total | N11: PPN 11% | O11: PPH 1,5 % | P11: Total Tghan | Q11: DISTRIBUTOR | R11: Harga Pokok | S11: Harga Pokok | T11: DISCOUNT DISTRIBUTOR | U11: JUMLAH | V11: TOTAL | W11: TOTAL PMBELIAN | X11: PPN | Y11: TOTAL
B12: Tanggal | C12: No. Faktur | F12: jml | G12: Satuan | H12: ( Rp ) | I12: ( Rp ) | J12: ( % ) | K12: Discon ( Rp ) | L12: setelah Disc | M12: Tagihan | P12: stlh PPN | R12: beli (Satuan) | S12: beli (Total) | T12: % | U12: DISC | V12: STLH DISC | W12: SBLM PPN
A13: 1 | B13: 45667 | C13: 117200125 | D13: PT Maimun Tuah Medika | E13: Glucose GOD-PAP LS 4x100ml mtd | F13: 2 | G13: kit | H13: 1372000 | I13: =SUM(F13*H13) -> 2744000 | J13: 0.25 | K13: =SUM(I13*J13) -> 686000 | L13: =SUM(I13-K13) -> 2058000 | M13: =SUM(L13:L16) -> 5558000 | N13: =SUM(M13*11%) -> 611380 | P13: =SUM(M13+N13) -> 6169380 | Q13: PT BAVARIA | R13: 420000 | S13: =SUM(F13*R13) -> 840000 | T13: 0 | U13: =SUM(S13*T13) -> 0 | V13: =SUM(S13-U13) -> 840000 | W13: =SUM(V13) -> 840000 | X13: 0.11 | Y13: =SUM(W13+(W13*X13)) -> 932400
E14: Urea Urease GLDH LS 4+1 UV 3x80ml mtd | F14: 1 | G14: kit | H14: 1960000 | I14: =SUM(F14*H14) -> 1960000 | J14: 0.25 | K14: =SUM(I14*J14) -> 490000 | L14: =SUM(I14-K14) -> 1470000 | Q14: PT BAVARIA | R14: 590000 | S14: =SUM(F14*R14) -> 590000 | T14: 0 | U14: =SUM(S14*T14) -> 0 | V14: =SUM(S14-U14) -> 590000 | W14: =SUM(V14) -> 590000 | X14: 0.11 | Y14: =SUM(W14+(W14*X14)) -> 654900
E15: GPT Alat IFCC LS 4+1 3x20 ml +1x15 ml mtd | F15: 2 | G15: kit | H15: 980000 | I15: =SUM(F15*H15) -> 1960000 | J15: 0.25 | K15: =SUM(I15*J15) -> 490000 | L15: =SUM(I15-K15) -> 1470000 | Q15: PT BAVARIA | R15: 300000 | S15: =SUM(F15*R15) -> 600000 | T15: 0 | U15: =SUM(S15*T15) -> 0 | V15: =SUM(S15-U15) -> 600000 | W15: =SUM(V15) -> 600000 | X15: 0.11 | Y15: =SUM(W15+(W15*X15)) -> 666000
E16: B30 Control Hematology 3 ml Mindray | F16: 1 | G16: vial | H16: 560000 | I16: =SUM(F16*H16) -> 560000 | J16: 0 | K16: =SUM(I16*J16) -> 0 | L16: =SUM(I16-K16) -> 560000 | Q16: PT TRIPATRIA ANDALAN MEDIKA | R16: 334000 | S16: =SUM(F16*R16) -> 334000 | T16: 0 | U16: =SUM(S16*T16) -> 0 | V16: =SUM(S16-U16) -> 334000 | W16: =SUM(V16) -> 334000 | X16: 0.11 | Y16: =SUM(W16+(W16*X16)) -> 370740
A17: 2 | B17: 45681 | C17: 117300125 | D17: PT Maimun Tuah Medika | E17: M30 CFL Lyse 500 ml Mindray | F17: 1 | G17: botol | H17: 1237000 | I17: =SUM(F17*H17) -> 1237000 | J17: 0 | K17: =SUM(I17*J17) -> 0 | L17: =SUM(I17-K17) -> 1237000 | M17: =SUM(L17:L19) -> 3022000 | N17: =SUM(M17*11%) -> 332420 | P17: =SUM(M17+N17) -> 3354420 | Q17: PT SMS | R17: 668000 | S17: =SUM(F17*R17) -> 668000 | T17: 0 | U17: =SUM(S17*T17) -> 0 | V17: =SUM(S17-U17) -> 668000 | W17: =SUM(V17) -> 668000 | X17: 0.11 | Y17: =SUM(W17+(W17*X17)) -> 741480
E18: Strip Urine WP-SU 10 G | F18: 3 | G18: box | H18: 350000 | I18: =SUM(F18*H18) -> 1050000 | J18: 0 | K18: =SUM(I18*J18) -> 0 | L18: =SUM(I18-K18) -> 1050000 | Q18: PT SMS | R18: 240000 | S18: =SUM(F18*R18) -> 720000 | T18: 0 | U18: =SUM(S18*T18) -> 0 | V18: =SUM(S18-U18) -> 720000 | W18: =SUM(V18) -> 720000 | X18: 0.11 | Y18: =SUM(W18+(W18*X18)) -> 799200
E19: GOT Asat IFCC LS 4+1 3x20 ml +1x15 ml mtd | F19: 1 | G19: kit | H19: 980000 | I19: =SUM(F19*H19) -> 980000 | J19: 0.25 | K19: =SUM(I19*J19) -> 245000 | L19: =SUM(I19-K19) -> 735000 | Q19: PT BAVARIA | R19: 300000 | S19: =SUM(F19*R19) -> 300000 | T19: 0 | U19: =SUM(S19*T19) -> 0 | V19: =SUM(S19-U19) -> 300000 | W19: =SUM(V19) -> 300000 | X19: 0.11 | Y19: =SUM(W19+(W19*X19)) -> 333000
A22: FEBRUARI 2025
A23: No. | B23: Faktur | D23: Nama Pelanggan | E23: Produk | F23: Quantity | H23: Harga Satuan | I23: Jumlah Harga | J23: Dics. | K23: Jumlah | L23: Jumlah | M23: Total | N23: PPN 11% | O23: PPH 1,5 % | P23: Total Tghan | Q23: DISTRIBUTOR | R23: Harga Pokok | S23: Harga Pokok | T23: DISCOUNT DISTRIBUTOR | U23: JUMLAH | V23: TOTAL | W23: TOTAL PMBELIAN | X23: PPN | Y23: TOTAL
B24: Tanggal | C24: No. Faktur | F24: jml | G24: Satuan | H24: ( Rp ) | I24: ( Rp ) | J24: ( % ) | K24: Discon ( Rp ) | L24: setelah Disc | M24: Tagihan | P24: stlh PPN | R24: beli (Satuan) | S24: beli (Total) | T24: % | U24: DISC | V24: STLH DISC | W24: SBLM PPN
A25: 1 | B25: 45334 | C25: 117440225 | D25: PT Maimun Tuah Medika | E25: Na/K/Cl 400ml Solution Pack Medica | F25: 2 | G25: pack | H25: 6164000 | I25: =SUM(F25*H25) -> 12328000 | J25: 0 | K25: =SUM(I25*J25) -> 0 | L25: =SUM(I25-K25) -> 12328000 | M25: =SUM(L25:L29) -> 15325438 | N25: =SUM(M25*11%) -> 1685798.1 | P25: =SUM(M25+N25) -> 17011236 | Q25: PRIMACO | R25: 4650000 | S25: =SUM(F25*R25) -> 9300000 | T25: 0.1 | U25: =SUM(S25*T25) -> 930000 | V25: =SUM(S25-U25) -> 8370000 | W25: =SUM(V25) -> 8370000 | X25: 0.11 | Y25: =SUM(W25+(W25*X25)) -> 9290700
E26: B30 Control Hematology 3 ml Mindray | F26: 1 | G26: vial | H26: 560000 | I26: =SUM(F26*H26) -> 560000 | J26: 0 | K26: =SUM(I26*J26) -> 0 | L26: =SUM(I26-K26) -> 560000 | Q26: PT TRIPATRIA ANDALAN MEDIKA | R26: 334000 | S26: =SUM(F26*R26) -> 334000 | T26: 0 | U26: =SUM(S26*T26) -> 0 | V26: =SUM(S26-U26) -> 334000 | W26: =SUM(V26) -> 334000 | X26: 0.11 | Y26: =SUM(W26+(W26*X26)) -> 370740
E27: Glucose GOD-PAP LS 4x100ml mtd | F27: 1 | G27: kit | H27: 1372000 | I27: =SUM(F27*H27) -> 1372000 | J27: 0.25 | K27: =SUM(I27*J27) -> 343000 | L27: =SUM(I27-K27) -> 1029000 | Q27: PT BAVARIA | R27: 420000 | S27: =SUM(F27*R27) -> 420000 | T27: 0 | U27: =SUM(S27*T27) -> 0 | V27: =SUM(S27-U27) -> 420000 | W27: =SUM(V27) -> 420000 | X27: 0.11 | Y27: =SUM(W27+(W27*X27)) -> 466200
E28: Cholesterol CHOD-PAP LS Mono 4x60ml+1x3ml mtd | F28: 1 | G28: kit | H28: 1531250 | I28: =SUM(F28*H28) -> 1531250 | J28: 0.25 | K28: =SUM(I28*J28) -> 382812.5 | L28: =SUM(I28-K28) -> 1148437.5 | Q28: PT BAVARIA | R28: 490000 | S28: =SUM(F28*R28) -> 490000 | T28: 0 | U28: =SUM(S28*T28) -> 0 | V28: =SUM(S28-U28) -> 490000 | W28: =SUM(V28) -> 490000 | X28: 0.11 | Y28: =SUM(W28+(W28*X28)) -> 543900
E29: Thermal Paper 4,9mm | F29: 10 | G29: roll | H29: 26000 | I29: =SUM(F29*H29) -> 260000 | J29: 0 | K29: =SUM(I29*J29) -> 0 | L29: =SUM(I29-K29) -> 260000 | Q29: PT SMS | R29: 14000 | S29: =SUM(F29*R29) -> 140000 | T29: 0 | U29: =SUM(S29*T29) -> 0 | V29: =SUM(S29-U29) -> 140000 | W29: =SUM(V29) -> 140000 | X29: 0.11 | Y29: =SUM(W29+(W29*X29)) -> 155400
A32: MARET 2025
A33: No. | B33: Faktur | D33: Nama Pelanggan | E33: Produk | F33: Quantity | H33: Harga Satuan | I33: Jumlah Harga | J33: Dics. | K33: Jumlah | L33: Jumlah | M33: Total | N33: PPN 11% | O33: PPH 1,5 % | P33: Total Tghan | Q33: DISTRIBUTOR | R33: Harga Pokok | S33: Harga Pokok | T33: DISCOUNT DISTRIBUTOR | U33: JUMLAH | V33: TOTAL | W33: TOTAL PMBELIAN | X33: PPN | Y33: TOTAL
B34: Tanggal | C34: No. Faktur | F34: jml | G34: Satuan | H34: ( Rp ) | I34: ( Rp ) | J34: ( % ) | K34: Discon ( Rp ) | L34: setelah Disc | M34: Tagihan | P34: stlh PPN | R34: beli (Satuan) | S34: beli (Total) | T34: % | U34: DISC | V34: STLH DISC | W34: SBLM PPN
A35: 14 | B35: 45368 | C35: 117870325 | D35: PT Maimun Tuah Medika | E35: Na/K/Cl 400ml Solution Pack Medica | F35: 1 | G35: pack | H35: 6164000 | I35: =SUM(F35*H35) -> 6164000 | J35: 0 | K35: =SUM(I35*J35) -> 0 | L35: =SUM(I35-K35) -> 6164000 | M35: =SUM(L35:L35) -> 6164000 | N35: =SUM(M35*11%) -> 678040 | P35: =SUM(M35+N35) -> 6842040 | Q35: PT PRIMACO | R35: 4650000 | S35: =SUM(F35*R35) -> 4650000 | T35: 0.1 | U35: =SUM(S35*T35) -> 465000 | V35: =SUM(S35-U35) -> 4185000 | W35: =SUM(V35) -> 4185000 | X35: 0.11 | Y35: =SUM(W35+(W35*X35)) -> 4645350

Sheet LAB BIOVITA
A1: BREAKDOWN PENJUALAN PT. MITRAJAYA SELARAS ABADI
A7: BREAKDOWN PENJUALAN PT. MITRAJAYA SELARAS ABADI 2025
A13: JANUARI 2025
A14: No. | B14: Faktur | D14: Sales | E14: Nama Pelanggan | F14: Kode | G14: Produk | H14: Quantity | J14: Harga Satuan | K14: Jumlah Harga | L14: Dics. | M14: Jumlah | N14: Jumlah | O14: Total | P14: PPN 11% | Q14: PPH 1,5 % | R14: Total Tghan | S14: DISTRIBUTOR | T14: Harga Pokok | U14: Harga Pokok | V14: DISCOUNT DISTRIBUTOR | W14: JUMLAH | X14: TOTAL | Y14: TOTAL PMBELIAN | Z14: PPN | AA14: TOTAL
B15: Tanggal | C15: No. Faktur | F15: Barang | H15: jml | I15: Satuan | J15: ( Rp ) | K15: ( Rp ) | L15: ( % ) | M15: Discon ( Rp ) | N15: setelah Disc | O15: Tagihan | R15: stlh PPN | T15: beli (Satuan) | U15: beli (Total) | V15: % | W15: DISC | X15: STLH DISC | Y15: SBLM PPN
A16: 1 | B16: 45670 | C16: 117220125 | E16: Lab Biovita | G16: Cup sample bertutup 1,5ml 500pcs/bag | H16: 1 | I16: bag | J16: 354839 | K16: =SUM(H16*J16) -> 354839 | L16: 0.2 | M16: =SUM(K16*L16) -> 70967.8 | N16: =SUM(K16-M16) -> 283871.2 | O16: =SUM(N16) -> 283871.2 | P16: =SUM(O16*11%) -> 31225.832 | R16: =SUM(O16+P16) -> 315097.03 | S16: PT GOLDEN PRATAMA | T16: 67500 | U16: =SUM(H16*T16) -> 67500 | V16: 0 | W16: =SUM(U16*V16) -> 0 | X16: =SUM(U16-W16) -> 67500 | Y16: =SUM(X16) -> 67500 | Z16: 0.11 | AA16: =SUM(Y16)+(Y16*Z16) -> 74925
A17: 2 | B17: 45674 | C17: 117260125 | E17: Lab Biovita | F17: PT | G17: Widal BAV | H17: 1 | I17: set | J17: 1000000 | K17: =SUM(H17*J17) -> 1000000 | L17: 0.2 | M17: =SUM(K17*L17) -> 200000 | N17: =SUM(K17-M17) -> 800000 | O17: =SUM(N17:N20) -> 9578632 | P17: =SUM(O17*11%) -> 1053649.5 | R17: =SUM(O17+P17) -> 10632282 | S17: PT BAVARIA | T17: 495495 | U17: =SUM(H17*T17) -> 495495 | V17: 0 | W17: =SUM(U17*V17) -> 0 | X17: =SUM(U17-W17) -> 495495 | Y17: =SUM(X17) -> 495495 | Z17: 0.11 | AA17: =SUM(Y17+(Y17*Z17)) -> 549999.45
G18: Blue tips | H18: 1 | I18: bag | J18: 161290 | K18: =SUM(H18*J18) -> 161290 | L18: 0.2 | M18: =SUM(K18*L18) -> 32258 | N18: =SUM(K18-M18) -> 129032 | S18: PT GOLDEN PRATAMA | T18: 40000 | U18: =SUM(H18*T18) -> 40000 | V18: 0 | W18: =SUM(U18*V18) -> 0 | X18: =SUM(U18-W18) -> 40000 | Y18: =SUM(X18) -> 40000 | Z18: 0.11 | AA18: =SUM(Y18)+(Y18*Z18) -> 44400
G19: HDL Direct 3x20ml + 1x20ml mtd | H19: 1 | I19: kit | J19: 10200000 | K19: =SUM(H19*J19) -> 10200000 | L19: 0.2 | M19: =SUM(K19*L19) -> 2040000 | N19: =SUM(K19-M19) -> 8160000 | S19: PT BAVARIA | T19: 1350000 | U19: =SUM(H19*T19) -> 1350000 | V19: 0 | W19: =SUM(V19) -> 0 | X19: =SUM(U19-W19) -> 1350000 | Y19: =SUM(X19) -> 1350000 | Z19: 0.11 | AA19: =SUM(Y19)+(Y19*Z19) -> 1498500
G20: ASO LATEX '50 Fortress | H20: 1 | I20: kit | J20: 612000 | K20: =SUM(H20*J20) -> 612000 | L20: 0.2 | M20: =SUM(K20*L20) -> 122400 | N20: =SUM(K20-M20) -> 489600 | S20: PT SETIA GUNA MEDIKA | T20: 394000 | U20: =SUM(H20*T20) -> 394000 | V20: 0.2 | W20: =SUM(U20*V20) -> 78800 | X20: =SUM(U20-W20) -> 315200 | Y20: =SUM(X20) -> 315200 | Z20: 0.11 | AA20: =SUM(Y20)+(Y20*Z20) -> 349872
A21: 3 | B21: 45674 | C21: 117270125 | E21: Lab Biovita | F21: PT | G21: Belt For Plate | H21: 1 | I21: unit | J21: 2667000 | K21: =SUM(H21*J21) -> 2667000 | L21: 0.1 | M21: =SUM(K21*L21) -> 266700 | N21: =SUM(K21-M21) -> 2400300 | O21: =SUM(N21:N22) -> 8100900 | P21: =SUM(O21*11%) -> 891099 | R21: =SUM(O21+P21) -> 8991999 | S21: PT BAVARIA | T21: 1600000 | U21: =SUM(H21*T21) -> 1600000 | V21: 0.4 | W21: =SUM(U21*V21) -> 640000 | X21: =SUM(U21-W21) -> 960000 | Y21: =SUM(X21) -> 960000 | Z21: 0.11 | AA21: =SUM(Y21+(Y21*Z21)) -> 1065600
G22: Sampling Probe Needle Only | H22: 1 | I22: unit | J22: 6334000 | K22: =SUM(H22*J22) -> 6334000 | L22: 0.1 | M22: =SUM(K22*L22) -> 633400 | N22: =SUM(K22-M22) -> 5700600 | S22: PT BAVARIA | T22: 3800000 | U22: =SUM(H22*T22) -> 3800000 | V22: 0.4 | W22: =SUM(U22*V22) -> 1520000 | X22: =SUM(U22-W22) -> 2280000 | Y22: =SUM(X22) -> 2280000 | Z22: 0.11 | AA22: =SUM(Y22)+(Y22*Z22) -> 2530800
A23: 4 | B23: 45688 | C23: 117350125 | E23: Lab Biovita | F23: PT | G23: HIV 1/2 Test Cassette '25 Test Orient Gene | H23: 1 | I23: box | J23: 781250 | K23: =SUM(H23*J23) -> 781250 | L23: 0.2 | M23: =SUM(K23*L23) -> 156250 | N23: =SUM(K23-M23) -> 625000 | O23: =SUM(N23:N25) -> 2884774.4 | P23: =SUM(O23*11%) -> 317325.18 | R23: =SUM(O23+P23) -> 3202099.6 | S23: PT LINTANG | T23: 450000 | U23: =SUM(H23*T23) -> 450000 | V23: 0.5 | W23: =SUM(U23*V23) -> 225000 | X23: =SUM(U23-W23) -> 225000 | Y23: =SUM(X23) -> 225000 | Z23: 0.11 | AA23: =SUM(Y23)+(Y23*Z23) -> 249750
G24: Dengue NS1 Test Cassette ‘25 Orientgene | H24: 1 | I24: box | J24: 2153750 | K24: =SUM(H24*J24) -> 2153750 | L24: 0.2 | M24: =SUM(K24*L24) -> 430750 | N24: =SUM(K24-M24) -> 1723000 | S24: PT LINTANG | T24: 1240000 | U24: =SUM(H24*T24) -> 1240000 | V24: 0.5 | W24: =SUM(U24*V24) -> 620000 | X24: =SUM(U24-W24) -> 620000 | Y24: =SUM(X24) -> 620000 | Z24: 0.11 | AA24: =SUM(Y24)+(Y24*Z24) -> 688200
G25: Syphillis strip '50 Orientgene | H25: 1 | I25: box | J25: 670968 | K25: =SUM(H25*J25) -> 670968 | L25: 0.2 | M25: =SUM(K25*L25) -> 134193.6 | N25: =SUM(K25-M25) -> 536774.4 | S25: PT LINTANG | T25: 380000 | U25: =SUM(H25*T25) -> 380000 | V25: 0.5 | W25: =SUM(U25*V25) -> 190000 | X25: =SUM(U25-W25) -> 190000 | Y25: =SUM(X25) -> 190000 | Z25: 0.11 | AA25: =SUM(Y25)+(Y25*Z25) -> 210900
A28: FEBRUARI 2025
A29: No. | B29: Faktur | D29: Sales | E29: Nama Pelanggan | F29: Kode | G29: Produk | H29: Quantity | J29: Harga Satuan | K29: Jumlah Harga | L29: Dics. | M29: Jumlah | N29: Jumlah | O29: Total | P29: PPN 11% | Q29: PPH 1,5 % | R29: Total Tghan | S29: DISTRIBUTOR | T29: Harga Pokok | U29: Harga Pokok | V29: DISCOUNT DISTRIBUTOR | W29: JUMLAH | X29: TOTAL | Y29: TOTAL PMBELIAN | Z29: PPN | AA29: TOTAL
B30: Tanggal | C30: No. Faktur | F30: Barang | H30: jml | I30: Satuan | J30: ( Rp ) | K30: ( Rp ) | L30: ( % ) | M30: Discon ( Rp ) | N30: setelah Disc | O30: Tagihan | R30: stlh PPN | T30: beli (Satuan) | U30: beli (Total) | V30: % | W30: DISC | X30: STLH DISC | Y30: SBLM PPN
A31: 1 | B31: 45702 | C31: 117470225 | E31: Lab Biovita | F31: PT | G31: M30 Diluent 20L Mindray | H31: 1 | I31: box | J31: 1686000 | K31: =SUM(H31*J31) -> 1686000 | L31: 0.2 | M31: =SUM(K31*L31) -> 337200 | N31: =SUM(K31-M31) -> 1348800 | O31: =SUM(N31:N33) -> 3282400 | P31: =SUM(O31*11%) -> 361064 | R31: =SUM(O31+P31) -> 3643464 | S31: PT TRIPATRIA ANDALAN MEDIKA | T31: 557000 | U31: =SUM(H31*T31) -> 557000 | V31: 0 | W31: =SUM(U31*V31) -> 0 | X31: =SUM(U31-W31) -> 557000 | Y31: =SUM(X31) -> 557000 | Z31: 0.11 | AA31: =SUM(Y31)+(Y31*Z31) -> 618270
G32: Probe Cleanser 50 ml Mindray | H32: 1 | I32: botol | J32: 376000 | K32: =SUM(H32*J32) -> 376000 | L32: 0.2 | M32: =SUM(K32*L32) -> 75200 | N32: =SUM(K32-M32) -> 300800 | S32: PT TRIPATRIA ANDALAN MEDIKA | T32: 150000 | U32: =SUM(H32*T32) -> 150000 | V32: 0 | W32: =SUM(U32*V32) -> 0 | X32: =SUM(U32-W32) -> 150000 | Y32: =SUM(X32) -> 150000 | Z32: 0.11 | AA32: =SUM(Y32)+(Y32*Z32) -> 166500
G33: M30 CFL Lyse 500 ml Mindray | H33: 1 | I33: botol | J33: 2041000 | K33: =SUM(H33*J33) -> 2041000 | L33: 0.2 | M33: =SUM(K33*L33) -> 408200 | N33: =SUM(K33-M33) -> 1632800 | S33: PT TRIPATRIA ANDALAN MEDIKA | T33: 607000 | U33: =SUM(H33*T33) -> 607000 | V33: 0 | W33: =SUM(U33*V33) -> 0 | X33: =SUM(U33-W33) -> 607000 | Y33: =SUM(X33) -> 607000 | Z33: 0.11 | AA33: =SUM(Y33)+(Y33*Z33) -> 673770
A34: 2 | B34: 45708 | C34: 117560225 | E34: Lab Biovita | F34: PT | G34: Gamma GT LS 4+1 3x40 ml+1x15 ml mtd | H34: 1 | I34: kit | J34: 3240000 | K34: =SUM(H34*J34) -> 3240000 | L34: 0.2 | M34: =SUM(K34*L34) -> 648000 | N34: =SUM(K34-M34) -> 2592000 | O34: =SUM(N34:N35) -> 3392000 | P34: =SUM(O34*11%) -> 373120 | R34: =SUM(O34+P34) -> 3765120 | S34: PT BAVARIA | T34: 530000 | U34: =SUM(H34*T34) -> 530000 | V34: 0 | W34: =SUM(V34) -> 0 | X34: =SUM(U34-W34) -> 530000 | Y34: =SUM(X34) -> 530000 | Z34: 0.11 | AA34: =SUM(Y34)+(Y34*Z34) -> 588300
G35: HBsAg Test Cassette '25 Device Orient Gene | H35: 2 | I35: box | J35: 500000 | K35: =SUM(H35*J35) -> 1000000 | L35: 0.2 | M35: =SUM(K35*L35) -> 200000 | N35: =SUM(K35-M35) -> 800000 | S35: PT LINTANG | T35: 260000 | U35: =SUM(H35*T35) -> 520000 | V35: 0.5 | W35: =SUM(U35*V35) -> 260000 | X35: =SUM(U35-W35) -> 260000 | Y35: =SUM(X35) -> 260000 | Z35: 0.11 | AA35: =SUM(Y35)+(Y35*Z35) -> 288600
A36: 3 | B36: 45716 | C36: 117690225 | E36: Lab Biovita | G36: Probe Cleanser 50 ml Mindray | H36: 1 | I36: botol | J36: 376000 | K36: =SUM(H36*J36) -> 376000 | L36: 0.2 | M36: =SUM(K36*L36) -> 75200 | N36: =SUM(K36-M36) -> 300800 | O36: =SUM(N36) -> 300800 | P36: =SUM(O36*11%) -> 33088 | R36: =SUM(O36+P36) -> 333888 | S36: PT TRIPATRIA ANDALAN MEDIKA | T36: 150000 | U36: =SUM(H36*T36) -> 150000 | V36: 0 | W36: =SUM(U36*V36) -> 0 | X36: =SUM(U36-W36) -> 150000 | Y36: =SUM(X36) -> 150000 | Z36: 0.11 | AA36: =SUM(Y36)+(Y36*Z36) -> 166500
A39: APRIL 2025
A40: No. | B40: Faktur | D40: Sales | E40: Nama Pelanggan | F40: Kode | G40: Produk | H40: Quantity | J40: Harga Satuan | K40: Jumlah Harga | L40: Dics. | M40: Jumlah | N40: Jumlah | O40: Total | P40: PPN 11% | Q40: PPH 1,5 % | R40: Total Tghan | S40: DISTRIBUTOR | T40: Harga Pokok | U40: Harga Pokok | V40: DISCOUNT DISTRIBUTOR | W40: JUMLAH | X40: TOTAL | Y40: TOTAL PMBELIAN | Z40: PPN | AA40: TOTAL
B41: Tanggal | C41: No. Faktur | F41: Barang | H41: jml | I41: Satuan | J41: ( Rp ) | K41: ( Rp ) | L41: ( % ) | M41: Discon ( Rp ) | N41: setelah Disc | O41: Tagihan | R41: stlh PPN | T41: beli (Satuan) | U41: beli (Total) | V41: % | W41: DISC | X41: STLH DISC | Y41: SBLM PPN
A42: 1 | B42: 45755 | C42: 118040425 | E42: Lab Biovita | F42: PT | G42: Needle Wing 23G BD | H42: 1 | I42: box | J42: 1230090 | K42: =SUM(H42*J42) -> 1230090 | L42: 0.2 | M42: =SUM(K42*L42) -> 246018 | N42: =SUM(K42-M42) -> 984072 | O42: =SUM(N42:N50) -> 24864944 | P42: =SUM(O42*11%) -> 2735143.8 | R42: =SUM(O42+P42) -> 27600088 | S42: PT AAM | T42: 649740 | U42: =SUM(H42*T42) -> 649740 | V42: 0.22 | W42: =SUM(U42*V42) -> 142942.8 | X42: =SUM(U42-W42) -> 506797.2 | Y42: =SUM(X42) -> 506797.2 | Z42: 0.11 | AA42: =SUM(Y42)+(Y42*Z42) -> 562544.89
G43: HDL Direct 3x20ml + 1x20ml mtd | H43: 1 | I43: kit | J43: 10200000 | K43: =SUM(H43*J43) -> 10200000 | L43: 0.2 | M43: =SUM(K43*L43) -> 2040000 | N43: =SUM(K43-M43) -> 8160000 | S43: PT BAVARIA | T43: 1350000 | U43: =SUM(H43*T43) -> 1350000 | V43: 0 | W43: =SUM(V43) -> 0 | X43: =SUM(U43-W43) -> 1350000 | Y43: =SUM(X43) -> 1350000 | Z43: 0.11 | AA43: =SUM(Y43)+(Y43*Z43) -> 1498500
G44: Cholesterol CHOD-PAP LS Mono 4x100ml mtd | H44: 1 | I44: kit | J44: 6000000 | K44: =SUM(H44*J44) -> 6000000 | L44: 0.2 | M44: =SUM(K44*L44) -> 1200000 | N44: =SUM(K44-M44) -> 4800000 | S44: PT BAVARIA | T44: 590000 | U44: =SUM(H44*T44) -> 590000 | V44: 0 | W44: =SUM(V44) -> 0 | X44: =SUM(U44-W44) -> 590000 | Y44: =SUM(X44) -> 590000 | Z44: 0.11 | AA44: =SUM(Y44)+(Y44*Z44) -> 654900
G45: Creatinine Kinetic LS 4+1 3x80 ml+1x60 ml mtd | H45: 1 | I45: pack | J45: 2025000 | K45: =SUM(H45*J45) -> 2025000 | L45: 0.2 | M45: =SUM(K45*L45) -> 405000 | N45: =SUM(K45-M45) -> 1620000 | S45: PT BAVARIA | T45: 490000 | U45: =SUM(H45*T45) -> 490000 | V45: 0 | W45: =SUM(U45*V45) -> 0 | X45: =SUM(U45-W45) -> 490000 | Y45: =SUM(X45) -> 490000 | Z45: 0.11 | AA45: =SUM(Y45)+(Y45*Z45) -> 543900
G46: Triglycerides GPO-PAP LS mono 4x100 ml mtd | H46: 1 | I46: kit | J46: 4431305 | K46: =SUM(H46*J46) -> 4431305 | L46: 0.2 | M46: =SUM(K46*L46) -> 886261 | N46: =SUM(K46-M46) -> 3545044 | S46: PT BAVARIA | T46: 1020000 | U46: =SUM(H46*T46) -> 1020000 | V46: 0 | W46: =SUM(U46*V46) -> 0 | X46: =SUM(U46-W46) -> 1020000 | Y46: =SUM(X46) -> 1020000 | Z46: 0.11 | AA46: =SUM(Y46)+(Y46*Z46) -> 1132200
G47: Pot Urine 50 cc tutup putih isi 100 pcs/pack | H47: 1 | I47: pack | J47: 258100 | K47: =SUM(H47*J47) -> 258100 | L47: 0.2 | M47: =SUM(K47*L47) -> 51620 | N47: =SUM(K47-M47) -> 206480 | S47: TOKO PLASTIK RAKYAT | T47: 60000 | U47: =SUM(H47*T47) -> 60000 | V47: 0 | W47: =SUM(U47*V47) -> 0 | X47: =SUM(U47-W47) -> 60000 | Y47: =SUM(X47) -> 60000 | Z47: 0 | AA47: =SUM(Y47)+(Y47*Z47) -> 60000
G48: HIV 1/2 Test Cassette '25 Test Orient Gene | H48: 2 | I48: box | J48: 781250 | K48: =SUM(H48*J48) -> 1562500 | L48: 0.2 | M48: =SUM(K48*L48) -> 312500 | N48: =SUM(K48-M48) -> 1250000 | S48: PT LINTANG | T48: 450000 | U48: =SUM(H48*T48) -> 900000 | V48: 0.5 | W48: =SUM(U48*V48) -> 450000 | X48: =SUM(U48-W48) -> 450000 | Y48: =SUM(X48) -> 450000 | Z48: 0.11 | AA48: =SUM(Y48)+(Y48*Z48) -> 499500
G49: Chemistry Control N 10x5 ml mtd | H49: 1 | I49: kit | J49: 5070435 | K49: =SUM(H49*J49) -> 5070435 | L49: 0.2 | M49: =SUM(K49*L49) -> 1014087 | N49: =SUM(K49-M49) -> 4056348 | S49: PT BAVARIA | T49: 1170000 | U49: =SUM(H49*T49) -> 1170000 | V49: 0 | W49: =SUM(U49*V49) -> 0 | X49: =SUM(U49-W49) -> 1170000 | Y49: =SUM(X49) -> 1170000 | Z49: 0.11 | AA49: =SUM(Y49)+(Y49*Z49) -> 1298700
G50: Micropore Plester 1 Inch (1 box isi 12 Roll) Winner | H50: 1 | I50: kit | J50: 303750 | K50: =SUM(H50*J50) -> 303750 | L50: 0.2 | M50: =SUM(K50*L50) -> 60750 | N50: =SUM(K50-M50) -> 243000 | S50: PASAR PRAMUKA | T50: 170000 | U50: =SUM(H50*T50) -> 170000 | V50: 0 | W50: =SUM(V50) -> 0 | X50: =SUM(U50-W50) -> 170000 | Y50: =SUM(X50) -> 170000 | Z50: 0.11 | AA50: =SUM(Y50)+(Y50*Z50) -> 188700
A51: 2 | B51: 45411 | C51: 118130425 | E51: Lab Biovita | F51: PT | G51: Reaction Cuvettes 6 Sector (120 cuv) | H51: 1 | I51: unit | J51: 18750000 | K51: =SUM(H51*J51) -> 18750000 | L51: 0.2 | M51: =SUM(K51*L51) -> 3750000 | N51: =SUM(K51-M51) -> 15000000 | O51: =SUM(N51:N52) -> 22600000 | P51: =SUM(O51*11%) -> 2486000 | R51: =SUM(O51+P51) -> 25086000 | S51: PT BAVARIA | T51: 15000000 | U51: =SUM(H51*T51) -> 15000000 | V51: 0.4 | W51: =SUM(U51*V51) -> 6000000 | X51: =SUM(U51-W51) -> 9000000 | Y51: =SUM(X51) -> 9000000 | Z51: 0.11 | AA51: =SUM(Y51)+(Y51*Z51) -> 9990000
G52: Halogen Lamp Assy (6V-10W) | H52: 1 | I52: unit | J52: 9500000 | K52: =SUM(H52*J52) -> 9500000 | L52: 0.2 | M52: =SUM(K52*L52) -> 1900000 | N52: =SUM(K52-M52) -> 7600000 | S52: PT BAVARIA | T52: 1600000 | U52: =SUM(H52*T52) -> 1600000 | V52: 0.4 | W52: =SUM(U52*V52) -> 640000 | X52: =SUM(U52-W52) -> 960000 | Y52: =SUM(X52) -> 960000 | Z52: 0.11 | AA52: =SUM(Y52)+(Y52*Z52) -> 1065600
A55: MEI 2025
A56: No. | B56: Faktur | D56: Sales | E56: Nama Pelanggan | F56: Kode | G56: Produk | H56: Quantity | J56: Harga Satuan | K56: Jumlah Harga | L56: Dics. | M56: Jumlah | N56: Jumlah | O56: Total | P56: PPN 11% | Q56: PPH 1,5 % | R56: Total Tghan | S56: DISTRIBUTOR | T56: Harga Pokok | U56: Harga Pokok | V56: DISCOUNT DISTRIBUTOR | W56: JUMLAH | X56: TOTAL | Y56: TOTAL PMBELIAN | Z56: PPN | AA56: TOTAL
...

Sheet JEC KEDOYA
A1: BREAKDOWN PENJUALAN PT. MITRAJAYA SELARAS ABADI
A5: 2025
A9: SEPTEMBER 2025
A10: No. | B10: Faktur | D10: Nama Pelanggan | E10: Produk | F10: Quantity | H10: Harga Satuan | I10: Jumlah Harga | J10: Dics. | K10: Jumlah | L10: Jumlah | M10: Total | N10: PPN 11% | O10: PPH 1,5 % | P10: Total Tghan | Q10: DISTRIBUTOR | R10: Harga Pokok | S10: Harga Pokok | T10: DISC DISTRIBUTOR | U10: JUMLAH | V10: TOTAL | W10: TOTAL PMBELIAN | X10: PPN | Y10: TOTAL
B11: Tanggal | C11: No. Faktur | F11: jml | G11: Satuan | H11: ( Rp ) | I11: ( Rp ) | J11: ( % ) | K11: Discon ( Rp ) | L11: setelah Disc | M11: Tagihan | P11: stlh PPN | R11: beli (Satuan) | S11: beli (Total) | T11: % | U11: DISC | V11: STLH DISC | W11: SBLM PPN
A12: 1 | B12: 45923 | C12: 119160925 | D12: JEC Kedoya | E12: Parafilm uk 2 Inch x 250FT | F12: 1 | G12: roll | H12: 990000 | I12: =SUM(F12*H12) -> 990000 | J12: 0 | K12: =SUM(I12*J12) -> 0 | L12: =SUM(I12-K12) -> 990000 | M12: =SUM(L12:L12) -> 990000 | N12: =SUM(M12*11%) -> 108900 | P12: =SUM(M12+N12) -> 1098900 | Q12: SMS Pramuka | R12: 550000 | S12: =SUM(F12*R12) -> 550000 | T12: 0 | U12: =SUM(S12*T12) -> 0 | V12: =SUM(S12-U12) -> 550000 | W12: =SUM(V12) -> 550000 | X12: 0.11 | Y12: =SUM(W12+(W12*X12)) -> 610500

Sheet JEC MENTENG
A1: BREAKDOWN PENJUALAN PT. MITRAJAYA SELARAS ABADI
A7: 2025
A12: JANUARI 2025
A13: No. | B13: Faktur | D13: Nama Pelanggan | E13: Produk | F13: Quantity | H13: Harga Satuan | I13: Jumlah Harga | J13: Dics. | K13: Jumlah | L13: Jumlah | M13: Total | N13: PPN 11% | O13: PPH 1,5 % | P13: Total Tghan | Q13: DISTRIBUTOR | R13: Harga Pokok | S13: Harga Pokok | T13: DISC DISTRIBUTOR | U13: JUMLAH | V13: TOTAL | W13: TOTAL PMBELIAN | X13: PPN | Y13: TOTAL
B14: Tanggal | C14: No. Faktur | F14: jml | G14: Satuan | H14: ( Rp ) | I14: ( Rp ) | J14: ( % ) | K14: Discon ( Rp ) | L14: setelah Disc | M14: Tagihan | P14: stlh PPN | R14: beli (Satuan) | S14: beli (Total) | T14: % | U14: DISC | V14: STLH DISC | W14: SBLM PPN
A15: 1 | B15: 45667 | C15: 117210125 | D15: JEC Menteng | E15: Blue Tips | F15: 2 | G15: pack | H15: 335000 | I15: =SUM(F15*H15) -> 670000 | J15: 0 | K15: =SUM(I15*J15) -> 0 | L15: =SUM(I15-K15) -> 670000 | M15: =SUM(L15:L15) -> 670000 | N15: =SUM(M15*11%) -> 73700 | P15: =SUM(M15+N15) -> 743700 | Q15: PT DJUNIAR & DJUNIAR | R15: 39000 | S15: =SUM(F15*R15) -> 78000 | T15: 0 | U15: =SUM(S15*T15) -> 0 | V15: =SUM(S15-U15) -> 78000 | W15: =SUM(V15) -> 78000 | X15: 0.11 | Y15: =SUM(W15+(W15*X15)) -> 86580
A18: APRIL 2025
A19: No. | B19: Faktur | D19: Nama Pelanggan | E19: Produk | F19: Quantity | H19: Harga Satuan | I19: Jumlah Harga | J19: Dics. | K19: Jumlah | L19: Jumlah | M19: Total | N19: PPN 11% | O19: PPH 1,5 % | P19: Total Tghan | Q19: DISTRIBUTOR | R19: Harga Pokok | S19: Harga Pokok | T19: DISC DISTRIBUTOR | U19: JUMLAH | V19: TOTAL | W19: TOTAL PMBELIAN | X19: PPN | Y19: TOTAL
B20: Tanggal | C20: No. Faktur | F20: jml | G20: Satuan | H20: ( Rp ) | I20: ( Rp ) | J20: ( % ) | K20: Discon ( Rp ) | L20: setelah Disc | M20: Tagihan | P20: stlh PPN | R20: beli (Satuan) | S20: beli (Total) | T20: % | U20: DISC | V20: STLH DISC | W20: SBLM PPN
A21: 1 | B21: 45378 | C21: 118050425 | D21: JEC Menteng | E21: Pewarna Gram 100 ml indoreagen | F21: 1 | G21: kit | H21: 815000 | I21: =SUM(F21*H21) -> 815000 | J21: 0.1 | K21: =SUM(I21*J21) -> 81500 | L21: =SUM(I21-K21) -> 733500 | M21: =SUM(L21:L21) -> 733500 | N21: =SUM(M21*11%) -> 80685 | P21: =SUM(M21+N21) -> 814185 | Q21: PT SHM | R21: 485000 | S21: =SUM(F21*R21) -> 485000 | T21: 0.25 | U21: =SUM(S21*T21) -> 121250 | V21: =SUM(S21-U21) -> 363750 | W21: =SUM(V21) -> 363750 | X21: 0.11 | Y21: =SUM(W21+(W21*X21)) -> 403762.5
A22: 2 | B22: 45397 | C22: 118060425 | D22: JEC Menteng | E22: Blue Tips | F22: 2 | G22: pack | H22: 335000 | I22: =SUM(F22*H22) -> 670000 | J22: 0 | K22: =SUM(I22*J22) -> 0 | L22: =SUM(I22-K22) -> 670000 | M22: =SUM(L22:L22) -> 670000 | N22: =SUM(M22*11%) -> 73700 | P22: =SUM(M22+N22) -> 743700 | Q22: PT DJUNIAR & DJUNIAR | R22: 39000 | S22: =SUM(F22*R22) -> 78000 | T22: 0 | U22: =SUM(S22*T22) -> 0 | V22: =SUM(S22-U22) -> 78000 | W22: =SUM(V22) -> 78000 | X22: 0.11 | Y22: =SUM(W22+(W22*X22)) -> 86580
A24: MEI 2025
A25: No. | B25: Faktur | D25: Nama Pelanggan | E25: Produk | F25: Quantity | H25: Harga Satuan | I25: Jumlah Harga | J25: Dics. | K25: Jumlah | L25: Jumlah | M25: Total | N25: PPN 11% | O25: PPH 1,5 % | P25: Total Tghan | Q25: DISTRIBUTOR | R25: Harga Pokok | S25: Harga Pokok | T25: DISC DISTRIBUTOR | U25: JUMLAH | V25: TOTAL | W25: TOTAL PMBELIAN | X25: PPN | Y25: TOTAL
B26: Tanggal | C26: No. Faktur | F26: jml | G26: Satuan | H26: ( Rp ) | I26: ( Rp ) | J26: ( % ) | K26: Discon ( Rp ) | L26: setelah Disc | M26: Tagihan | P26: stlh PPN | R26: beli (Satuan) | S26: beli (Total) | T26: % | U26: DISC | V26: STLH DISC | W26: SBLM PPN
A27: 1 | B27: 45417 | C27: 118160524 | D27: JEC Menteng | E27: Larutan KOH 10% 100ml | F27: 1 | G27: botol | H27: 67000 | I27: =SUM(F27*H27) -> 67000 | J27: 0 | K27: =SUM(I27*J27) -> 0 | L27: =SUM(I27-K27) -> 67000 | M27: =SUM(L27:L29) -> 1637000 | N27: =SUM(M27*11%) -> 180070 | P27: =SUM(M27+N27) -> 1817070 | Q27: PT SHM | R27: 35200 | S27: =SUM(F27*R27) -> 35200 | T27: 0.25 | U27: =SUM(S27*T27) -> 8800 | V27: =SUM(S27-U27) -> 26400 | W27: =SUM(V27) -> 26400 | X27: 0.11 | Y27: =SUM(W27+(W27*X27)) -> 29304
E28: Blue Tips | F28: 2 | G28: pack | H28: 335000 | I28: =SUM(F28*H28) -> 670000 | J28: 0 | K28: =SUM(I28*J28) -> 0 | L28: =SUM(I28-K28) -> 670000 | Q28: PT DJUNIAR & DJUNIAR | R28: 39000 | S28: =SUM(F28*R28) -> 78000 | T28: 0 | U28: =SUM(S28*T28) -> 0 | V28: =SUM(S28-U28) -> 78000 | W28: =SUM(V28) -> 78000 | X28: 0.11 | Y28: =SUM(W28+(W28*X28)) -> 86580
E29: Pewarna Wright 1x100ml | F29: 1 | G29: botol | H29: 900000 | I29: =SUM(F29*H29) -> 900000 | J29: 0 | K29: =SUM(I29*J29) -> 0 | L29: =SUM(I29-K29) -> 900000 | N29: =SUM(M29*11%) -> 0 | Q29: PT SHM | R29: 300000 | S29: =SUM(F29*R29) -> 300000 | T29: 0.25 | U29: =SUM(S29*T29) -> 75000 | V29: =SUM(S29-U29) -> 225000 | W29: =SUM(V29) -> 225000 | X29: 0.11 | Y29: =SUM(W29+(W29*X29)) -> 249750
A31: JUNI 2025
A32: No. | B32: Faktur | D32: Nama Pelanggan | E32: Produk | F32: Quantity | H32: Harga Satuan | I32: Jumlah Harga | J32: Dics. | K32: Jumlah | L32: Jumlah | M32: Total | N32: PPN 11% | O32: PPH 1,5 % | P32: Total Tghan | Q32: DISTRIBUTOR | R32: Harga Pokok | S32: Harga Pokok | T32: DISC DISTRIBUTOR | U32: JUMLAH | V32: TOTAL | W32: TOTAL PMBELIAN | X32: PPN | Y32: TOTAL
B33: Tanggal | C33: No. Faktur | F33: jml | G33: Satuan | H33: ( Rp ) | I33: ( Rp ) | J33: ( % ) | K33: Discon ( Rp ) | L33: setelah Disc | M33: Tagihan | P33: stlh PPN | R33: beli (Satuan) | S33: beli (Total) | T33: % | U33: DISC | V33: STLH DISC | W33: SBLM PPN
A34: 1 | B34: 45849 | C34: 118730725 | D34: JEC Menteng | E34: Yellow Tips | F34: 2 | G34: pack | H34: 335000 | I34: =SUM(F34*H34) -> 670000 | J34: 0 | K34: =SUM(I34*J34) -> 0 | L34: =SUM(I34-K34) -> 670000 | M34: =SUM(L34:L34) -> 670000 | N34: =SUM(M34*11%) -> 73700 | P34: =SUM(M34+N34) -> 743700 | Q34: PT VIPRO | R34: 23636 | S34: =SUM(F34*R34) -> 47272 | T34: 0 | U34: =SUM(S34*T34) -> 0 | V34: =SUM(S34-U34) -> 47272 | W34: =SUM(V34) -> 47272 | X34: 0.11 | Y34: =SUM(W34+(W34*X34)) -> 52471.92
A37: AGUSTUS 2025
A38: No. | B38: Faktur | D38: Nama Pelanggan | E38: Produk | F38: Quantity | H38: Harga Satuan | I38: Jumlah Harga | J38: Dics. | K38: Jumlah | L38: Jumlah | M38: Total | N38: PPN 11% | O38: PPH 1,5 % | P38: Total Tghan | Q38: DISTRIBUTOR | R38: Harga Pokok | S38: Harga Pokok | T38: DISC DISTRIBUTOR | U38: JUMLAH | V38: TOTAL | W38: TOTAL PMBELIAN | X38: PPN | Y38: TOTAL
B39: Tanggal | C39: No. Faktur | F39: jml | G39: Satuan | H39: ( Rp ) | I39: ( Rp ) | J39: ( % ) | K39: Discon ( Rp ) | L39: setelah Disc | M39: Tagihan | P39: stlh PPN | R39: beli (Satuan) | S39: beli (Total) | T39: % | U39: DISC | V39: STLH DISC | W39: SBLM PPN
A40: 1 | B40: 45875 | C40: 118850824 | D40: JEC Menteng | E40: Blue Tips | F40: 1 | G40: pack | H40: 335000 | I40: =SUM(F40*H40) -> 335000 | J40: 0 | K40: =SUM(I40*J40) -> 0 | L40: =SUM(I40-K40) -> 335000 | M40: =SUM(L40:L41) -> 670000 | N40: =SUM(M40*11%) -> 73700 | P40: =SUM(M40+N40) -> 743700 | Q40: PT DJUNIAR & DJUNIAR | R40: 39000 | S40: =SUM(F40*R40) -> 39000 | T40: 0 | U40: =SUM(S40*T40) -> 0 | V40: =SUM(S40-U40) -> 39000 | W40: =SUM(V40) -> 39000 | X40: 0.11 | Y40: =SUM(W40+(W40*X40)) -> 43290
E41: Yellow Tips | F41: 1 | G41: pack | H41: 335000 | I41: =SUM(F41*H41) -> 335000 | J41: 0 | K41: =SUM(I41*J41) -> 0 | L41: =SUM(I41-K41) -> 335000 | Q41: PT VIPRO | R41: 23636 | S41: =SUM(F41*R41) -> 23636 | T41: 0 | U41: =SUM(S41*T41) -> 0 | V41: =SUM(S41-U41) -> 23636 | W41: =SUM(V41) -> 23636 | X41: 0.11 | Y41: =SUM(W41+(W41*X41)) -> 26235.96
A42: 2 | B42: 45888 | C42: 118930825 | D42: JEC Menteng | E42: Parafilm uk 2 Inch x 250FT | F42: 1 | G42: roll | H42: 990000 | I42: =SUM(F42*H42) -> 990000 | J42: 0 | K42: =SUM(I42*J42) -> 0 | L42: =SUM(I42-K42) -> 990000 | M42: =SUM(L42:L42) -> 990000 | N42: =SUM(M42*11%) -> 108900 | P42: =SUM(M42+N42) -> 1098900 | Q42: SMS Pramuka | R42: 550000 | S42: =SUM(F42*R42) -> 550000 | T42: 0 | U42: =SUM(S42*T42) -> 0 | V42: =SUM(S42-U42) -> 550000 | W42: =SUM(V42) -> 550000 | X42: 0.11 | Y42: =SUM(W42+(W42*X42)) -> 610500
A43: 3 | B43: 45894 | C43: 118970825 | D43: JEC Menteng | E43: Blue Tips | F43: 2 | G43: pack | H43: 335000 | I43: =SUM(F43*H43) -> 670000 | J43: 0 | K43: =SUM(I43*J43) -> 0 | L43: =SUM(I43-K43) -> 670000 | M43: =SUM(L43:L43) -> 670000 | N43: =SUM(M43*11%) -> 73700 | P43: =SUM(M43+N43) -> 743700 | Q43: PT DJUNIAR & DJUNIAR | R43: 39000 | S43: =SUM(F43*R43) -> 78000 | T43: 0 | U43: =SUM(S43*T43) -> 0 | V43: =SUM(S43-U43) -> 78000 | W43: =SUM(V43) -> 78000 | X43: 0.11 | Y43: =SUM(W43+(W43*X43)) -> 86580
A45: SEPTEMBER 2025
A46: No. | B46: Faktur | D46: Nama Pelanggan | E46: Produk | F46: Quantity | H46: Harga Satuan | I46: Jumlah Harga | J46: Dics. | K46: Jumlah | L46: Jumlah | M46: Total | N46: PPN 11% | O46: PPH 1,5 % | P46: Total Tghan | Q46: DISTRIBUTOR | R46: Harga Pokok | S46: Harga Pokok | T46: DISC DISTRIBUTOR | U46: JUMLAH | V46: TOTAL | W46: TOTAL PMBELIAN | X46: PPN | Y46: TOTAL
B47: Tanggal | C47: No. Faktur | F47: jml | G47: Satuan | H47: ( Rp ) | I47: ( Rp ) | J47: ( % ) | K47: Discon ( Rp ) | L47: setelah Disc | M47: Tagihan | P47: stlh PPN | R47: beli (Satuan) | S47: beli (Total) | T47: % | U47: DISC | V47: STLH DISC | W47: SBLM PPN
A48: 1 | B48: 45917 | C48: 119130925 | D48: JEC Menteng | E48: Parafilm uk 2 Inch x 250FT | F48: 1 | G48: roll | H48: 990000 | I48: =SUM(F48*H48) -> 990000 | J48: 0 | K48: =SUM(I48*J48) -> 0 | L48: =SUM(I48-K48) -> 990000 | M48: =SUM(L48:L49) -> 1638000 | N48: =SUM(M48*11%) -> 180180 | P48: =SUM(M48+N48) -> 1818180 | Q48: SMS Pramuka | R48: 550000 | S48: =SUM(F48*R48) -> 550000 | T48: 0 | U48: =SUM(S48*T48) -> 0 | V48: =SUM(S48-U48) -> 550000 | W48: =SUM(V48) -> 550000 | X48: 0.11 | Y48: =SUM(W48+(W48*X48)) -> 610500
E49: Uri Check 10L | F49: 1 | G49: botol | H49: 648000 | I49: =SUM(F49*H49) -> 648000 | J49: 0 | K49: =SUM(I49*J49) -> 0 | L49: =SUM(I49-K49) -> 648000 | Q49: PT FOKUS DIAGNOSTIG | R49: 577500 | S49: =SUM(F49*R49) -> 577500 | T49: 0.2 | U49: =SUM(S49*T49) -> 115500 | V49: =SUM(S49-U49) -> 462000 | W49: =SUM(V49) -> 462000 | X49: 0.11 | Y49: =SUM(W49+(W49*X49)) -> 512820
A51: OKTOBER 2025
A52: No. | B52: Faktur | D52: Nama Pelanggan | E52: Produk | F52: Quantity | H52: Harga Satuan | I52: Jumlah Harga | J52: Dics. | K52: Jumlah | L52: Jumlah | M52: Total | N52: PPN 11% | O52: PPH 1,5 % | P52: Total Tghan | Q52: DISTRIBUTOR | R52: Harga Pokok | S52: Harga Pokok | T52: DISC DISTRIBUTOR | U52: JUMLAH | V52: TOTAL | W52: TOTAL PMBELIAN | X52: PPN | Y52: TOTAL
B53: Tanggal | C53: No. Faktur | F53: jml | G53: Satuan | H53: ( Rp ) | I53: ( Rp ) | J53: ( % ) | K53: Discon ( Rp ) | L53: setelah Disc | M53: Tagihan | P53: stlh PPN | R53: beli (Satuan) | S53: beli (Total) | T53: % | U53: DISC | V53: STLH DISC | W53: SBLM PPN
A54: 1 | B54: 45933 | C54: 119261025 | D54: JEC Menteng | E54: Blue Tips | F54: 2 | G54: pack | H54: 335000 | I54: =SUM(F54*H54) -> 670000 | J54: 0 | K54: =SUM(I54*J54) -> 0 | L54: =SUM(I54-K54) -> 670000 | M54: =SUM(L54:L55) -> 1340000 | N54: =SUM(M54*11%) -> 147400 | P54: =SUM(M54+N54) -> 1487400 | Q54: PT DJUNIAR & DJUNIAR | R54: 39000 | S54: =SUM(F54*R54) -> 78000 | T54: 0 | U54: =SUM(S54*T54) -> 0 | V54: =SUM(S54-U54) -> 78000 | W54: =SUM(V54) -> 78000 | X54: 0.11 | Y54: =SUM(W54+(W54*X54)) -> 86580
E55: Yellow Tips | F55: 2 | G55: pack | H55: 335000 | I55: =SUM(F55*H55) -> 670000 | J55: 0 | K55: =SUM(I55*J55) -> 0 | L55: =SUM(I55-K55) -> 670000 | Q55: PT VIPRO | R55: 23636 | S55: =SUM(F55*R55) -> 47272 | T55: 0 | U55: =SUM(S55*T55) -> 0 | V55: =SUM(S55-U55) -> 47272 | W55: =SUM(V55) -> 47272 | X55: 0.11 | Y55: =SUM(W55+(W55*X55)) -> 52471.92
A57: NOVEMBER 2025
A58: No. | B58: Faktur | D58: Nama Pelanggan | E58: Produk | F58: Quantity | H58: Harga Satuan | I58: Jumlah Harga | J58: Dics. | K58: Jumlah | L58: Jumlah | M58: Total | N58: PPN 11% | O58: PPH 1,5 % | P58: Total Tghan | Q58: DISTRIBUTOR | R58: Harga Pokok | S58: Harga Pokok | T58: DISC DISTRIBUTOR | U58: JUMLAH | V58: TOTAL | W58: TOTAL PMBELIAN | X58: PPN | Y58: TOTAL
...

Sheet JEC BEKASI
A1: BREAKDOWN PENJUALAN PT. MITRAJAYA SELARAS ABADI
A5: 2025
A9: NOVEMBER 2025
A10: No. | B10: Faktur | D10: Nama Pelanggan | E10: Produk | F10: Quantity | H10: Harga Satuan | I10: Jumlah Harga | J10: Dics. | K10: Jumlah | L10: Jumlah | M10: Total | N10: PPN 11% | O10: PPH 1,5 % | P10: Total Tghan | Q10: DISTRIBUTOR | R10: Harga Pokok | S10: Harga Pokok | T10: DISC DISTRIBUTOR | U10: JUMLAH | V10: TOTAL | W10: TOTAL PMBELIAN | X10: PPN | Y10: TOTAL
B11: Tanggal | C11: No. Faktur | F11: jml | G11: Satuan | H11: ( Rp ) | I11: ( Rp ) | J11: ( % ) | K11: Discon ( Rp ) | L11: setelah Disc | M11: Tagihan | P11: stlh PPN | R11: beli (Satuan) | S11: beli (Total) | T11: % | U11: DISC | V11: STLH DISC | W11: SBLM PPN
A12: 1 | B12: 45988 | C12: 119701125 | D12: JEC Bekasi | E12: Parafilm uk 2 Inch x 250FT | F12: 1 | G12: roll | H12: 990000 | I12: =SUM(F12*H12) -> 990000 | J12: 0 | K12: =SUM(I12*J12) -> 0 | L12: =SUM(I12-K12) -> 990000 | M12: =SUM(L12:L12) -> 990000 | N12: =SUM(M12*11%) -> 108900 | P12: =SUM(M12+N12) -> 1098900 | Q12: SMS Pramuka | R12: 550000 | S12: =SUM(F12*R12) -> 550000 | T12: 0 | U12: =SUM(S12*T12) -> 0 | V12: =SUM(S12-U12) -> 550000 | W12: =SUM(V12) -> 550000 | X12: 0.11 | Y12: =SUM(W12+(W12*X12)) -> 610500

Sheet LK ZAM ZAM
A1: BREAKDOWN PENJUALAN PT. MITRAJAYA SELARAS ABADI
A9: 2025
A16: FEBRUARI 2025
A17: No. | B17: Faktur | D17: Nama Pelanggan | E17: Produk | F17: Quantity | H17: Harga Satuan | I17: Jumlah Harga | J17: Dics. | K17: Jumlah | L17: Jumlah | M17: Total | N17: PPN 11% | O17: PPH 1,5 % | P17: Total Tghan | Q17: DISTRIBUTOR | R17: Harga Pokok | S17: Harga Pokok | T17: DISCOUNT DISTRIBUTOR | U17: JUMLAH | V17: TOTAL | W17: TOTAL PMBELIAN | X17: PPN | Y17: TOTAL
B18: Tanggal | C18: No. Faktur | F18: jml | G18: Satuan | H18: ( Rp ) | I18: ( Rp ) | J18: ( % ) | K18: Discon ( Rp ) | L18: setelah Disc | M18: Tagihan | P18: stlh PPN | R18: beli (Satuan) | S18: beli (Total) | T18: % | U18: DISC | V18: STLH DISC | W18: SBLM PPN
A19: 1 | B19: 45705 | C19: 117540225 | D19: Klinik Pratama Zam Zam Medika | E19: M30 Diluent 20L Mindray | F19: 1 | G19: box | H19: 2237000 | I19: =SUM(F19*H19) -> 2237000 | J19: 0.3 | K19: =SUM(I19*J19) -> 671100 | L19: =SUM(I19-K19) -> 1565900 | M19: =SUM(L19:L21) -> 3335150 | N19: =SUM(M19*11%) -> 366866.5 | P19: =SUM(M19+N19) -> 3702016.5 | Q19: PT SMS | R19: 613000 | S19: =SUM(F19*R19) -> 613000 | T19: 0 | U19: =SUM(S19*T19) -> 0 | V19: =SUM(S19-U19) -> 613000 | W19: =SUM(V19) -> 613000 | X19: 0.11 | Y19: =SUM(W19+(W19*X19)) -> 680430
E20: Probe Cleanser 50 ml Mindray | F20: 3 | G20: botol | H20: 485000 | I20: =SUM(F20*H20) -> 1455000 | J20: 0.3 | K20: =SUM(I20*J20) -> 436500 | L20: =SUM(I20-K20) -> 1018500 | Q20: PT PT TRIPATRIA ANDALAN MEDIKA | R20: 150000 | S20: =SUM(F20*R20) -> 450000 | T20: 0 | U20: =SUM(S20*T20) -> 0 | V20: =SUM(S20-U20) -> 450000 | W20: =SUM(V20) -> 450000 | X20: 0.11 | Y20: =SUM(W20+(W20*X20)) -> 499500
E21: Widal BAV | F21: 1 | G21: set | H21: 1072500 | I21: =SUM(F21*H21) -> 1072500 | J21: 0.3 | K21: =SUM(I21*J21) -> 321750 | L21: =SUM(I21-K21) -> 750750 | P21: =SUM(M21+N21) -> 0 | Q21: PT BAVARIA | R21: 495495 | S21: =SUM(F21*R21) -> 495495 | T21: 0 | U21: =SUM(S21*T21) -> 0 | V21: =SUM(S21-U21) -> 495495 | W21: =SUM(V21) -> 495495 | X21: 0.11 | Y21: =SUM(W21+(W21*X21)) -> 549999.45
A23: FEBRUARI 2025
A24: No. | B24: Faktur | D24: Nama Pelanggan | E24: Produk | F24: Quantity | H24: Harga Satuan | I24: Jumlah Harga | J24: Dics. | K24: Jumlah | L24: Jumlah | M24: Total | N24: PPN 11% | O24: PPH 1,5 % | P24: Total Tghan | Q24: DISTRIBUTOR | R24: Harga Pokok | S24: Harga Pokok | T24: DISCOUNT DISTRIBUTOR | U24: JUMLAH | V24: TOTAL | W24: TOTAL PMBELIAN | X24: PPN | Y24: TOTAL
B25: Tanggal | C25: No. Faktur | F25: jml | G25: Satuan | H25: ( Rp ) | I25: ( Rp ) | J25: ( % ) | K25: Discon ( Rp ) | L25: setelah Disc | M25: Tagihan | P25: stlh PPN | R25: beli (Satuan) | S25: beli (Total) | T25: % | U25: DISC | V25: STLH DISC | W25: SBLM PPN
A26: 1 | B26: 45719 | C26: 118440625 | D26: Klinik Pratama Zam Zam Medika | E26: M30 Diluent 20L Mindray | F26: 1 | G26: box | H26: 2237000 | I26: =SUM(F26*H26) -> 2237000 | J26: 0.3 | K26: =SUM(I26*J26) -> 671100 | L26: =SUM(I26-K26) -> 1565900 | M26: =SUM(L26:L28) -> 3882550 | N26: =SUM(M26*11%) -> 427080.5 | P26: =SUM(M26+N26) -> 4309630.5 | Q26: PT SMS | R26: 613000 | S26: =SUM(F26*R26) -> 613000 | T26: 0 | U26: =SUM(S26*T26) -> 0 | V26: =SUM(S26-U26) -> 613000 | W26: =SUM(V26) -> 613000 | X26: 0.11 | Y26: =SUM(W26+(W26*X26)) -> 680430
E27: M30 CFL Lyse 500 ml Mindray | F27: 1 | G27: botol | H27: 2237000 | I27: =SUM(F27*H27) -> 2237000 | J27: 0.3 | K27: =SUM(I27*J27) -> 671100 | L27: =SUM(I27-K27) -> 1565900 | Q27: PT SMS | R27: 607000 | S27: =SUM(F27*R27) -> 607000 | T27: 0 | U27: =SUM(S27*T27) -> 0 | V27: =SUM(S27-U27) -> 607000 | W27: =SUM(V27) -> 607000 | X27: 0.11 | Y27: =SUM(W27+(W27*X27)) -> 673770
E28: Widal BAV | F28: 1 | G28: set | H28: 1072500 | I28: =SUM(F28*H28) -> 1072500 | J28: 0.3 | K28: =SUM(I28*J28) -> 321750 | L28: =SUM(I28-K28) -> 750750 | P28: =SUM(M28+N28) -> 0 | Q28: PT BAVARIA | R28: 495495 | S28: =SUM(F28*R28) -> 495495 | T28: 0 | U28: =SUM(S28*T28) -> 0 | V28: =SUM(S28-U28) -> 495495 | W28: =SUM(V28) -> 495495 | X28: 0.11 | Y28: =SUM(W28+(W28*X28)) -> 549999.45
A31: SEPTEMBER 2025
A32: No. | B32: Faktur | D32: Nama Pelanggan | E32: Produk | F32: Quantity | H32: Harga Satuan | I32: Jumlah Harga | J32: Dics. | K32: Jumlah | L32: Jumlah | M32: Total | N32: PPN 11% | O32: PPH 1,5 % | P32: Total Tghan | Q32: DISTRIBUTOR | R32: Harga Pokok | S32: Harga Pokok | T32: DISCOUNT DISTRIBUTOR | U32: JUMLAH | V32: TOTAL | W32: TOTAL PMBELIAN | X32: PPN | Y32: TOTAL
B33: Tanggal | C33: No. Faktur | F33: jml | G33: Satuan | H33: ( Rp ) | I33: ( Rp ) | J33: ( % ) | K33: Discon ( Rp ) | L33: setelah Disc | M33: Tagihan | P33: stlh PPN | R33: beli (Satuan) | S33: beli (Total) | T33: % | U33: DISC | V33: STLH DISC | W33: SBLM PPN
A34: 1 | B34: 45926 | C34: 119190925 | D34: Klinik Pratama Zam Zam Medika | E34: M30 Diluent 20L Mindray | F34: 1 | G34: box | H34: 2237000 | I34: =SUM(F34*H34) -> 2237000 | J34: 0.3 | K34: =SUM(I34*J34) -> 671100 | L34: =SUM(I34-K34) -> 1565900 | M34: =SUM(L34:L37) -> 3795300 | N34: =SUM(M34*11%) -> 417483 | P34: =SUM(M34+N34) -> 4212783 | Q34: PT TRIPATRIA | R34: 613000 | S34: =SUM(F34*R34) -> 613000 | T34: 0 | U34: =SUM(S34*T34) -> 0 | V34: =SUM(S34-U34) -> 613000 | W34: =SUM(V34) -> 613000 | X34: 0.11 | Y34: =SUM(W34+(W34*X34)) -> 680430
E35: SGPT 3x40 ml+1x30 ml mtd | F35: 1 | G35: kit | H35: 1396000 | I35: =SUM(F35*H35) -> 1396000 | J35: 0.3 | K35: =SUM(I35*J35) -> 418800 | L35: =SUM(I35-K35) -> 977200 | Q35: BAVARIA | R35: 400000 | S35: =SUM(F35*R35) -> 400000 | T35: 0 | U35: =SUM(S35*T35) -> 0 | V35: 400000 | W35: =SUM(V35) -> 400000 | X35: 0.11 | Y35: =SUM(W35+(W35*X35)) -> 444000
E36: SGOT 3x40 ml+1x30 ml mtd | F36: 1 | G36: kit | H36: 1396000 | I36: =SUM(F36*H36) -> 1396000 | J36: 0.3 | K36: =SUM(I36*J36) -> 418800 | L36: =SUM(I36-K36) -> 977200 | Q36: BAVARIA | R36: 400000 | S36: =SUM(F36*R36) -> 400000 | T36: 0 | U36: =SUM(S36*T36) -> 0 | V36: 400000 | W36: =SUM(V36) -> 400000 | X36: 0.11 | Y36: =SUM(W36+(W36*X36)) -> 444000
E37: Thermal Paper 4,9mm | F37: 5 | G37: rol | H37: 55000 | I37: =SUM(F37*H37) -> 275000 | J37: 0 | K37: =SUM(I37*J37) -> 0 | L37: =SUM(I37-K37) -> 275000 | Q37: PT SMS | R37: 14000 | S37: =SUM(F37*R37) -> 70000 | T37: 0 | U37: =SUM(S37*T37) -> 0 | V37: =SUM(S37-U37) -> 70000 | W37: =SUM(V37) -> 70000 | X37: 0.11 | Y37: =SUM(W37+(W37*X37)) -> 77700

Sheet PT Najib Sukses Banjarmasin
A1: BREAKDOWN PENJUALAN PT. MITRAJAYA SELARAS ABADI
A5: 2025
A8: JANUARI 2025
A9: No. | B9: Faktur | D9: Sales | E9: Nama Pelanggan | F9: Produk | G9: Quantity | I9: Harga Satuan | J9: Jumlah Harga | K9: Dics. | L9: Jumlah | M9: Jumlah | N9: Total | O9: PPN 11% | P9: PPH 1,5 % | Q9: Total Tghan | R9: DISTRIBUTOR | S9: Harga Pokok | T9: Harga Pokok | U9: DISCOUNT DISTRIBUTOR | V9: JUMLAH | W9: TOTAL | X9: TOTAL PMBELIAN | Y9: PPN | Z9: TOTAL
B10: Tanggal | C10: No. Faktur | G10: jml | H10: Satuan | I10: ( Rp ) | J10: ( Rp ) | K10: ( % ) | L10: Discon ( Rp ) | M10: setelah Disc | N10: Tagihan | Q10: stlh PPN | S10: beli (Satuan) | T10: beli (Total) | U10: % | V10: DISC | W10: STLH DISC | X10: SBLM PPN
A11: 1 | B11: 45664 | C11: 117170125 | E11: PT Najib Sukses Banjarmasin | F11: HDL Cholesterol 54 ml Mindray | G11: 2 | H11: kit | I11: 3609000 | J11: =SUM(G11*I11) -> 7218000 | K11: 0.3 | L11: =SUM(J11*K11) -> 2165400 | M11: =SUM(J11-L11) -> 5052600 | N11: =SUM(M11:M18) -> 21247100 | O11: =SUM(N11*11%) -> 2337181 | Q11: =SUM(N11+O11) -> 23584281 | R11: PT TRIPATRIA ANDALAN MEDIKA | S11: 1561285 | T11: =SUM(G11*S11) -> 3122570 | U11: 0 | V11: =SUM(T11*U11) -> 0 | W11: =SUM(T11-V11) -> 3122570 | X11: =SUM(W11) -> 3122570 | Y11: 0.11 | Z11: =SUM(X11+(X11*Y11)) -> 3466052.7
